Traceback (most recent call last):
  File "/home/wxt/.conda/envs/rl/lib/python3.10/site-packages/transformers/utils/hub.py", line 399, in cached_file
    resolved_file = hf_hub_download(
  File "/home/wxt/.conda/envs/rl/lib/python3.10/site-packages/huggingface_hub/utils/_validators.py", line 106, in _inner_fn
    validate_repo_id(arg_value)
  File "/home/wxt/.conda/envs/rl/lib/python3.10/site-packages/huggingface_hub/utils/_validators.py", line 160, in validate_repo_id
    raise HFValidationError(
huggingface_hub.errors.HFValidationError: Repo id must use alphanumeric chars or '-', '_', '.', '--' and '..' are forbidden, '-' and '.' cannot start or end the name, max length is 96: 'reward_model_path OpenAssistant/oasst-rm-2.1-pythia-1.4b-epoch-2.5'.
The above exception was the direct cause of the following exception:
Traceback (most recent call last):
  File "/home/wxt/huatong/TRL_FT/train_code/ppo_train.py", line 124, in <module>
    rm_tokenizer = AutoTokenizer.from_pretrained(reward_model_name)
  File "/home/wxt/.conda/envs/rl/lib/python3.10/site-packages/transformers/models/auto/tokenization_auto.py", line 817, in from_pretrained
    tokenizer_config = get_tokenizer_config(pretrained_model_name_or_path, **kwargs)
  File "/home/wxt/.conda/envs/rl/lib/python3.10/site-packages/transformers/models/auto/tokenization_auto.py", line 649, in get_tokenizer_config
    resolved_config_file = cached_file(
  File "/home/wxt/.conda/envs/rl/lib/python3.10/site-packages/transformers/utils/hub.py", line 463, in cached_file
    raise EnvironmentError(
OSError: Incorrect path_or_model_id: 'reward_model_path OpenAssistant/oasst-rm-2.1-pythia-1.4b-epoch-2.5'. Please provide either the path to a local folder or the repo_id of a model on the Hub.